using cvt archive
no kmeans
[36m[2023-07-02 19:21:03,673][167435] Environment ant, action_dim=8, obs_dim=87
[36m[2023-07-02 19:21:07,597][167435] Created Scheduler for cma_maega with an archive learning rate of 0.1, and add mode batch, using solution dim 28816 and archive dims [7, 7, 7, 7, 7, 7]. Min threshold is -500.0. Restart rule is no_improvement
Traceback (most recent call last):
  File "/home/icaros/anaconda3/envs/ppga/lib/python3.9/runpy.py", line 197, in _run_module_as_main
    return _run_code(code, main_globals, None,
  File "/home/icaros/anaconda3/envs/ppga/lib/python3.9/runpy.py", line 87, in _run_code
    exec(code, run_globals)
  File "/home/icaros/Documents/PPGADev/algorithm/train_ppga.py", line 575, in <module>
    train_ppga(cfg, vec_env)
  File "/home/icaros/Documents/PPGADev/algorithm/train_ppga.py", line 398, in train_ppga
    objs, measures, jacobian, metadata = ppo.train(vec_env=vec_env,
  File "/home/icaros/Documents/PPGADev/RL/ppo.py", line 319, in train
    action, logprob, _ = self.vec_inference.get_action(self.next_obs)
  File "/home/icaros/Documents/PPGADev/models/vectorized.py", line 146, in get_action
    action_mean = self.actor_mean(obs)
  File "/home/icaros/anaconda3/envs/ppga/lib/python3.9/site-packages/torch/nn/modules/module.py", line 1190, in _call_impl
    return forward_call(*input, **kwargs)
  File "/home/icaros/anaconda3/envs/ppga/lib/python3.9/site-packages/torch/nn/modules/container.py", line 204, in forward
    input = module(input)
  File "/home/icaros/anaconda3/envs/ppga/lib/python3.9/site-packages/torch/nn/modules/module.py", line 1190, in _call_impl
    return forward_call(*input, **kwargs)
  File "/home/icaros/Documents/PPGADev/models/vectorized.py", line 22, in forward
    x = torch.reshape(x, (-1, obs_per_weight, x.shape[1]))
RuntimeError: shape '[-1, 428, 87]' is invalid for input of size 261000
Traceback (most recent call last):
  File "/home/icaros/anaconda3/envs/ppga/lib/python3.9/runpy.py", line 197, in _run_module_as_main
    return _run_code(code, main_globals, None,
  File "/home/icaros/anaconda3/envs/ppga/lib/python3.9/runpy.py", line 87, in _run_code
    exec(code, run_globals)
  File "/home/icaros/Documents/PPGADev/algorithm/train_ppga.py", line 575, in <module>
    train_ppga(cfg, vec_env)
  File "/home/icaros/Documents/PPGADev/algorithm/train_ppga.py", line 398, in train_ppga
    objs, measures, jacobian, metadata = ppo.train(vec_env=vec_env,
  File "/home/icaros/Documents/PPGADev/RL/ppo.py", line 319, in train
    action, logprob, _ = self.vec_inference.get_action(self.next_obs)
  File "/home/icaros/Documents/PPGADev/models/vectorized.py", line 146, in get_action
    action_mean = self.actor_mean(obs)
  File "/home/icaros/anaconda3/envs/ppga/lib/python3.9/site-packages/torch/nn/modules/module.py", line 1190, in _call_impl
    return forward_call(*input, **kwargs)
  File "/home/icaros/anaconda3/envs/ppga/lib/python3.9/site-packages/torch/nn/modules/container.py", line 204, in forward
    input = module(input)
  File "/home/icaros/anaconda3/envs/ppga/lib/python3.9/site-packages/torch/nn/modules/module.py", line 1190, in _call_impl
    return forward_call(*input, **kwargs)
  File "/home/icaros/Documents/PPGADev/models/vectorized.py", line 22, in forward
    x = torch.reshape(x, (-1, obs_per_weight, x.shape[1]))
RuntimeError: shape '[-1, 428, 87]' is invalid for input of size 261000